Workbook
Name Linking_1: Inputs!$B$3:$E$52
Name Linking_2: 'Tier Breakdown'!$B$6:$P$62
Name Linking_3: 'Global S_D (incl. Agentic)'!$B$16:$F$23
Name Linking_3: 'Global S_D'!$B$16:$F$23

Sheet Inputs
B2: Assumptions (blue = inputs, black = derived) | D2: Agentic as a % of Regular Users | F2: ='Tier Breakdown'!D3 -> 0.15
B3: Category | C3: Assumption | D3: Units / Notes | E3: Non- Agentic Value | F3: Agentic Assumptions | G3: Multiple | H3: Change Rationale
B4: Demand | C4: WAU (weekly active users) | D4: user-provided | E4: ='Tier Breakdown'!D2*10^6 -> 1000000000 | F4: =E4*F2*'Tier Breakdown'!D4 -> 1500000000 | G4: =IFERROR(F4/E4,1) -> 1.5 | H4: ="Assumes "&TEXT(F2,"#%")&" Users use Agentic" -> Assumes 15% Users use Agentic
B5: Demand | C5: DAU/WAU | D5: % | E5: 0.3 | F5: 0.5 | G5: 0.1
B6: Demand | C6: DAU | D6: # | E6: =E4*E5 -> 300000000 | F6: =F4*F5 -> 750000000 | G6: 0.1
B7: Demand | C7: Daily Queries per user | D7: Queries | E7: 10 | F7: 20 | G7: 0.1
B8: Demand | C8: Peak to average ratio | D8: (x) | E8: 3 | F8: 3 | G8: 0.1
B9: Demand | C9: Peak QPS | D9: req/s | E9: =E6*E7*E8/86400 -> 104166.67 | F9: =F6*F7*F8/86400 -> 520833.33 | G9: =IFERROR(F9/E9,1) -> 5
B10: Demand | C10: Input tokens / request | D10: tokens | E10: 500 | F10: 35000 | G10: =IFERROR(F10/E10,1) -> 70 | H10: Agents require full codebase context, tool definitions, and conversation history to function, routinely filling 50-100K context windows.
B11: Demand | C11: RAG tokens / request | D11: RAG/Input 2:1 (in practice 2:1 - 10:1) | E11: =E10*2 -> 1000 | F11: 50000 | G11: =IFERROR(F11/E11,1) -> 50 | H11: Agents retrieve entire files, multiple documentation sections, and perform multi-hop retrieval rather than fetching a few text chunks.
B12: Demand | C12: Output tokens / request | D12: Input/output 3:1 | E12: =E10/3 -> 166.66667 | F12: 5000 | G12: =IFERROR(F12/E12,1) -> 30 | H12: Code files and reasoning outputs produce 30-50x internal tokens than visible output
B13: Demand | C13: Total tokens / request | D13: tokens | E13: =E10+E11+E12 -> 1666.6667 | F13: =F10+F11+F12 -> 90000 | G13: =IFERROR(F13/E13,1) -> 54
B14: Demand | C14: Peak-day tokens processed | D14: tokens/day (given) | E14: =E15 -> 1.5e+13 | F14: =F9*F13*86400 -> 4.05e+15 | G14: =IFERROR(F14/E14,1) -> 270
B15: Demand | C15: Peak-day tokens processed (from QPS) | D15: tokens/day (QPS × tokens/req × 86400) | E15: =E9*E13*86400 -> 1.5e+13 | F15: =F9*F13*86400 -> 4.05e+15 | G15: =IFERROR(F15/E15,1) -> 270 | H15: Check this with Expert
B16: Demand | C16: Active prefill sequences | D16: Peak QPS: 300,000 req/s; TTFT: 1.0 s | E16: 300000 | F16: =F9 -> 520833.33 | G16: =IFERROR(F16/E16,1) -> 1.7361111
B17: Demand | C17: Active decode sequences | D17: Decode speed: 60 tokens/sec/request | E17: 1500000 | F17: =F9*F12/60 -> 43402778 | G17: =IFERROR(F17/E17,1) -> 28.935185
B18: Demand | C18: Active total sequences | D18: given | E18: =E16+E17 -> 1800000 | F18: =F16+F17 -> 43923611 | G18: =IFERROR(F18/E18,1) -> 24.402006
B19: KV | C19: KV precision (bytes/elem) | D19: FP16 KV => 2 bytes | E19: 2 | F19: 2 | G19: =IFERROR(F19/E19,1) -> 1
B20: KV | C20: Layers (L) | E20: 96 | F20: 96 | G20: =IFERROR(F20/E20,1) -> 1
B21: KV | C21: KV heads (Hkv) | D21: GQA | E21: 8 | F21: 8 | G21: =IFERROR(F21/E21,1) -> 1
B22: KV | C22: Head dim (Dhead) | E22: 128 | F22: 128 | G22: =IFERROR(F22/E22,1) -> 1
B23: KV | C23: KV bytes / token | D23: bytes (formula: 2*L*Hkv*Dhead*bytes/elem) | E23: =2*E20*E21*E22*E19 -> 393216 | F23: =2*F20*F21*F22*F19 -> 393216 | G23: =IFERROR(F23/E23,1) -> 1
B24: KV | C24: KV bytes / token (given) | D24: bytes (384 KiB) | E24: 393216 | F24: 393216 | G24: =IFERROR(F24/E24,1) -> 1
B25: KV | C25: Effective live window | D25: tokens | E25: 1024 | F25: 1024 | G25: =IFERROR(F25/E25,1) -> 1
B26: KV | C26: Live KV / sequence | D26: bytes (KV bytes/token × live window) | E26: =E23*E25 -> 402653184 | F26: =F23*F25 -> 402653184 | G26: =IFERROR(F26/E26,1) -> 1
B27: KV | C27: Live KV total (all active seqs) | D27: bytes | E27: =E26*E18 -> 724775731200000 | F27: =F26*F18 -> 1.7685982e+16 | G27: =IFERROR(F27/E27,1) -> 24.402006
B28: KV Split (Live) | C28: HBM fraction | E28: 0.5 | F28: 0.5 | G28: =IFERROR(F28/E28,1) -> 1
B29: KV Split (Live) | C29: DRAM fraction | E29: 0.5 | F29: 0.5 | G29: =IFERROR(F29/E29,1) -> 1
B30: KV Split (Live) | C30: Rack SSD fraction | E30: 0 | F30: 0 | G30: =IFERROR(F30/E30,1) -> 1
B31: KV Split (Live) | C31: HBM live KV | D31: bytes | E31: =E27*E28 -> 362387865600000 | F31: =F27*F28 -> 8.8429909e+15 | G31: =IFERROR(F31/E31,1) -> 24.402006
B32: KV Split (Live) | C32: DRAM live KV | D32: bytes | E32: =E27*E29 -> 362387865600000 | F32: =F27*F29 -> 8.8429909e+15 | G32: =IFERROR(F32/E32,1) -> 24.402006
B33: KV Split (Live) | C33: Rack SSD live KV | D33: bytes | E33: =E27*E30 -> 0 | F33: =F27*F30 -> 0 | G33: =IFERROR(F33/E33,1) -> 1
B34: KV Reuse Cache | C34: Retention window | D34: hours | E34: 24 | F34: 24 | G34: =IFERROR(F34/E34,1) -> 1
B35: KV Reuse Cache | C35: Reuse fraction of processed tokens | D35: 50% | E35: 0.5 | F35: 0.85 | G35: =IFERROR(F35/E35,1) -> 1.7
B36: KV Reuse Cache | C36: Stored in tier | D36: 40% DRAM / 60% Rack SSD | E36: 0.6 | F36: 0.4 | G36: =IFERROR(F36/E36,1) -> 0.66666667
B37: KV Reuse Cache | C37: Tokens in retention window | D37: tokens (peak-day × retention/24h) | E37: =E14*(E34/24) -> 1.5e+13 | F37: =F14*(F34/24) -> 4.05e+15 | G37: =IFERROR(F37/E37,1) -> 270
B38: KV Reuse Cache | C38: Retained KV bytes | D38: bytes (tokens × reuse% × KV bytes/token) | E38: =E37*E35*E23 -> 2.94912e+18 | F38: =F37*F35*F23 -> 1.3536461e+21 | G38: =IFERROR(F38/E38,1) -> 459
B39: Topology | C39: Sequences per replica | D39: per 8-GPU replica | E39: 2500 | F39: 2500 | G39: =IFERROR(F39/E39,1) -> 1
B40: Topology | C40: Replicas | D40: given | E40: =E43/E41 -> 131250 | F40: =F43/F41 -> 2343750 | G40: =IFERROR(F40/E40,1) -> 17.857143
B41: Topology | C41: GPUs per replica | E41: 8 | F41: 8 | G41: =IFERROR(F41/E41,1) -> 1
...

Sheet Tier Breakdown
A1: x | L1: x | Q1: x
B2: Weekly Average Users (M) | D2: 1000
B3: % of WAU Agentic | D3: 0.15
B4: Overlap Multiplier (Users using multiple Agents) | D4: 10
B6: Tier | C6: Component | D6: Total Non Agentic (bytes) | E6: Total Agentic (bytes) | F6: Total (TiB) | G6: Total (PiB) | I6: Non Agentic (EiB) | J6: Agentic (EiB) | K6: Total (EiB) | N6: Per GPU (GiB) | O6: Per Node (TB dec)
B7: Demand | C7: =Inputs!C10 -> Input tokens / request | D7: =Inputs!E10 -> 500 | E7: =Inputs!F10 -> 35000 | F7: =SUM(D7:E7)/1024^4 -> 3.2287062e-08 | G7: =F7/1024 -> 3.1530334e-11 | I7: =D7/1024^6 -> 4.3368087e-16 | J7: =E7/1024^6 -> 3.0357661e-14 | K7: =SUM(I7:J7) -> 3.0791342e-14
B8: Demand | C8: ="(+) "&Inputs!C11 -> (+) RAG tokens / request | D8: =Inputs!E11 -> 1000 | E8: =Inputs!F11 -> 50000 | F8: =SUM(D8:E8)/1024^4 -> 4.638423e-08 | G8: =F8/1024 -> 4.5297099e-11 | I8: =D8/1024^6 -> 8.6736174e-16 | J8: =E8/1024^6 -> 4.3368087e-14 | K8: =SUM(I8:J8) -> 4.4235449e-14
B9: Demand | C9: ="(+) "&Inputs!C12 -> (+) Output tokens / request | D9: =Inputs!E12 -> 166.66667 | E9: =Inputs!F12 -> 5000 | F9: =SUM(D9:E9)/1024^4 -> 4.699056e-09 | G9: =F9/1024 -> 4.5889218e-12 | I9: =D9/1024^6 -> 1.4456029e-16 | J9: =E9/1024^6 -> 4.3368087e-15 | K9: =SUM(I9:J9) -> 4.481369e-15
B10: Demand | C10: Total Tokens / request | D10: =SUM(D7:D9) -> 1666.6667 | E10: =SUM(E7:E9) -> 90000 | F10: =SUM(D10:E10)/1024^4 -> 8.3370348e-08 | G10: =F10/1024 -> 8.1416355e-11 | I10: =D10/1024^6 -> 1.4456029e-15 | J10: =E10/1024^6 -> 7.8062556e-14 | K10: =SUM(I10:J10) -> 7.9508159e-14
B11: Demand | C11: ="(x) "&Inputs!C9 -> (x) Peak QPS | D11: =Inputs!E9 -> 104166.67 | E11: =Inputs!F9 -> 520833.33 | F11: =SUM(D11:E11)/1024^4 -> 5.6843419e-07 | G11: =F11/1024 -> 5.5511151e-10 | I11: =D11/1024^6 -> 9.0350181e-14 | J11: =E11/1024^6 -> 4.5175091e-13 | K11: =SUM(I11:J11) -> 5.4210109e-13
B12: Demand | C12: Peak-day Tokens Processed | D12: =D10*D11*86400 -> 1.5e+13 | E12: =E10*E11*86400 -> 4.05e+15 | F12: =SUM(D12:E12)/1024^4 -> 3697.096 | G12: =F12/1024 -> 3.6104453 | I12: =D12/1024^6 -> 1.3010426e-05 | J12: =E12/1024^6 -> 0.003512815 | K12: =SUM(I12:J12) -> 0.0035258255
B14: Units | C14: Active Prefill Sequences | D14: =Inputs!E16 -> 300000 | E14: =Inputs!F16 -> 520833.33 | F14: =SUM(D14:E14)/1024^4 -> 7.4654357e-07 | G14: =F14/1024 -> 7.2904645e-10 | I14: =D14/1024^6 -> 2.6020852e-13 | J14: =E14/1024^6 -> 4.5175091e-13 | K14: =SUM(I14:J14) -> 7.1195943e-13
B15: Units | C15: (+) Active Decode Sequences | D15: =Inputs!E17 -> 1500000 | E15: =Inputs!F17 -> 43402778 | F15: =SUM(D15:E15)/1024^4 -> 4.0838838e-05 | G15: =F15/1024 -> 3.9881678e-08 | I15: =D15/1024^6 -> 1.3010426e-12 | J15: =E15/1024^6 -> 3.7645909e-11 | K15: =SUM(I15:J15) -> 3.8946951e-11
B16: Units | C16: Active Total Sequences | D16: =SUM(D14:D15) -> 1800000 | E16: =SUM(E14:E15) -> 43923611 | F16: =SUM(D16:E16)/1024^4 -> 4.1585382e-05 | G16: =F16/1024 -> 4.0610725e-08 | I16: =D16/1024^6 -> 1.5612511e-12 | J16: =E16/1024^6 -> 3.809766e-11 | K16: =SUM(I16:J16) -> 3.9658911e-11
B17: Bytes | C17: ="(x) "&Inputs!C26 -> (x) Live KV / sequence | D17: =Inputs!E26 -> 402653184 | E17: =Inputs!F26 -> 402653184 | F17: =SUM(D17:E17)/1024^4 -> 0.00073242188 | G17: =F17/1024 -> 7.1525574e-07 | I17: =D17/1024^6 -> 3.4924597e-10 | J17: =E17/1024^6 -> 3.4924597e-10 | K17: =SUM(I17:J17) -> 6.9849193e-10
B18: Bytes | C18: =Inputs!C27 -> Live KV total (all active seqs) | D18: =Inputs!E27 -> 724775731200000 | E18: =Inputs!F27 -> 1.7685982e+16 | F18: =SUM(D18:E18)/1024^4 -> 16744.486 | G18: =F18/1024 -> 16.352038 | I18: =D18/1024^6 -> 0.00062864274 | J18: =E18/1024^6 -> 0.015340144 | K18: =SUM(I18:J18) -> 0.015968787
C19: Memo: HBM Fraction | D19: =Inputs!E28 -> 0.5 | E19: =Inputs!F28 -> 0.5
C20: Memo: DRAM Fraction | D20: =Inputs!E29 -> 0.5 | E20: =Inputs!F29 -> 0.5
B22: KV | C22: KV Retention Window (hours) | D22: =Inputs!E34 -> 24 | E22: =Inputs!F34 -> 24
B23: KV | C23: (x) Reuse Fraction of Processed Tokens | D23: =Inputs!E35 -> 0.5 | E23: =Inputs!F35 -> 0.85
B24: KV | C24: (x) KV Bytes / token | D24: =Inputs!E23 -> 393216 | E24: =Inputs!F23 -> 393216
B25: KV | C25: ="(x) "&C12 -> (x) Peak-day Tokens Processed | D25: =D12 -> 1.5e+13 | E25: =E12 -> 4.05e+15
B26: KV | C26: Retained KV Bytes | D26: =PRODUCT(D22:D25)/24 -> 2.94912e+18 | E26: =PRODUCT(E22:E25)/24 -> 1.3536461e+21 | F26: =SUM(D26:E26)/1024^4 -> 1.2338161e+09 | G26: =F26/1024 -> 1204898.6 | I26: =D26/1024^6 -> 2.5579538 | J26: =E26/1024^6 -> 1174.1008 | K26: =SUM(I26:J26) -> 1176.6588
B27: KV | C27: (x) DRAM Fraction | D27: =Inputs!E36 -> 0.6 | E27: =Inputs!F36 -> 0.4
B28: DRAM | C28: KV reuse cache | D28: =D26*D27 -> 1.769472e+18 | E28: =E26*E27 -> 5.4145843e+20 | F28: =SUM(D28:E28)/1024^4 -> 4.940629e+08 | G28: =F28/1024 -> 482483.3 | I28: =D28/1024^6 -> 1.5347723 | J28: =E28/1024^6 -> 469.64033 | K28: =SUM(I28:J28) -> 471.1751
B29: Rack SSD | C29: KV reuse cache | D29: =D26-D28 -> 1.179648e+18 | E29: =E26-E28 -> 8.1218765e+20 | F29: =SUM(D29:E29)/1024^4 -> 7.3975325e+08 | G29: =F29/1024 -> 722415.28 | I29: =D29/1024^6 -> 1.0231815 | J29: =E29/1024^6 -> 704.46049 | K29: =SUM(I29:J29) -> 705.48367
B31: Local Cache | C31: Nodes | D31: =Inputs!E44 -> 131250 | E31: =Inputs!F44 -> 2343750 | F31: =SUM(D31:E31)/1024^4 -> 2.2509994e-06 | G31: =SUM(E31:F31)/1024^4 -> 2.1316282e-06 | I31: =D31/1024^6 -> 1.1384123e-13 | J31: =E31/1024^6 -> 2.0328791e-12 | K31: =F31/1024^6 -> 1.9524307e-24
B32: Local Cache | C32: (x) Local Rack SSD / Node | D32: =Inputs!E48*10^12 -> 100000000000000 | E32: =Inputs!F48*10^12 -> 100000000000000 | F32: =SUM(D32:E32)/1024^4 -> 181.89894 | G32: =SUM(E32:F32)/1024^4 -> 90.94947 | I32: =D32/1024^6 -> 8.6736174e-05 | J32: =E32/1024^6 -> 8.6736174e-05 | K32: =F32/1024^6 -> 1.5777218e-16
B33: Rack SSD | C33: Local Rack SSD caches/logs | D33: =D31*D32 -> 1.3125e+19 | E33: =E31*E32 -> 2.34375e+20 | F33: =F31*F32 -> 0.0004094544 | G33: =G31*G32 -> 0.00019387046 | I33: =I31*I32 -> 9.8741525e-18 | J33: =J31*J32 -> 1.7632415e-16 | K33: =K31*K32 -> 3.0803926e-40
B35: NAND | C35: WAU | D35: =Inputs!E4 -> 1000000000 | E35: =Inputs!F4 -> 1500000000
B36: NAND | C36: Avg RAG Raw Upload | D36: =Inputs!E67*10^9 -> 25000000 | E36: =Inputs!F67*10^9 -> 500000000
B37: NAND | C37: Embedding + Index Inflation vs raw (x) | D37: =Inputs!E68+Inputs!E69 -> 4.5 | E37: =Inputs!F68+Inputs!F69 -> 5.5
B38: NAND | C38: Retention Window | D38: =Inputs!E70 -> 12 | E38: =Inputs!F70 -> 12
B39: NAND | C39: Capacity Multiplier (Replication+EC+Overhead) | D39: =Inputs!E71 -> 3 | E39: =Inputs!F71 -> 3
B40: NAND | C40: RAG Physical Bytes | D40: =D35*D36*D37*D38*4.345*D39 -> 1.759725e+19 | E40: =E35*E36*E37*E38*4.345*E39 -> 6.452325e+20 | F40: =SUM(D40:E40)/1024^4 -> 6.0284015e+08 | G40: =SUM(E40:F40)/1024^4 -> 5.8683554e+08 | I40: =D40/1024^6 -> 15.263181 | J40: =E40/1024^6 -> 559.64998 | K40: =SUM(I40:J40) -> 574.91316
B41: NAND | C41: (+) Logs Logical Bytes | D41: =Inputs!E79 -> 1.2e+19 | E41: =Inputs!F79 -> 6e+18 | F41: =SUM(D41:E41)/1024^4 -> 16370905 | G41: =SUM(E41:F41)/1024^4 -> 5456968.2 | I41: =D41/1024^6 -> 10.408341 | J41: =E41/1024^6 -> 5.2041704 | K41: =SUM(I41:J41) -> 15.612511
B42: NAND | C42: Datalake Total Bytes | D42: =SUM(D40:D41) -> 2.959725e+19 | E42: =SUM(E40:E41) -> 6.512325e+20 | F42: =SUM(D42:E42)/1024^4 -> 6.1921105e+08 | G42: =SUM(E42:F42)/1024^4 -> 5.9229251e+08 | I42: =D42/1024^6 -> 25.671522 | J42: =E42/1024^6 -> 564.85415 | K42: =SUM(I42:J42) -> 590.52568
A44: x | B44: Tier | C44: Component | D44: Total Non Agentic (bytes) | E44: Total Agentic (bytes) | F44: Total (TiB) | G44: Total (PiB) | I44: Non Agentic (EiB) | J44: Agentic (EiB) | K44: Total (EiB)
B45: HBM | C45: Live KV (hot) | D45: =Inputs!E31 -> 362387865600000 | E45: =Inputs!F31 -> 8.8429909e+15 | F45: =SUM(D45:E45)/1024^4 -> 8372.2432 | G45: =F45/1024 -> 8.1760188 | I45: =D45/1024^6 -> 0.00031432137 | J45: =E45/1024^6 -> 0.007670072 | K45: =SUM(I45:J45) -> 0.0079843934 | N45: =Inputs!E31/Inputs!E43/1024^3 -> 0.32142857
B46: DRAM | C46: Live KV (warm) | D46: =Inputs!E32 -> 362387865600000 | E46: =Inputs!F32 -> 8.8429909e+15 | F46: =SUM(D46:E46)/1024^4 -> 8372.2432 | G46: =F46/1024 -> 8.1760188 | I46: =D46/1024^6 -> 0.00031432137 | J46: =E46/1024^6 -> 0.007670072 | K46: =SUM(I46:J46) -> 0.0079843934
...

Sheet Frank Inputs
B2: Frank
B4: Queries per Day | D4: 3000
B5: Messages | D5: 50000
B6: % Input / Output | D6: =45/50 -> 0.9
B7: Input | D7: =D5*D6 -> 45000
B8: % Rag | D8: =40/45 -> 0.88888889
B10: Input | D10: =D7-D11 -> 5000
B11: Rag | D11: =D8*D7 -> 40000
B12: Output | D12: =D5-D7 -> 5000
B14: Layers (x) Complexity | D14: 1.5
B16: Effective Live Window | D16: 100000

Sheet Sensitivity_Input_Length
B2: Input tokens / request | C2: HBM TOTAL (TB) | D2: DRAM TOTAL (TB) | E2: Rack SSD TOTAL (TB) | F2: Datalake TOTAL (TB)
B3: 2000 | C3: 226290.73 | D3: 4585261.2 | E3: 46877348 | F3: 293556000
B4: 5000 | C4: 226290.73 | D4: 6648465.6 | E4: 49972154 | F4: 293556000
B5: 10000 | C5: 226290.73 | D5: 10087140 | E5: 55130165 | F5: 293556000
B6: 20000 | C6: 226290.73 | D6: 16964487 | E6: 65446187 | F6: 293556000
B7: 50000 | C7: 226290.73 | D7: 37596531 | E7: 96394252 | F7: 293556000
B8: 100000 | C8: 226290.73 | D8: 71983270 | E8: 1.4797436e+08 | F8: 293556000
B9: 200000 | C9: 226290.73 | D9: 1.4075675e+08 | E9: 2.5113458e+08 | F9: 293556000

Sheet Global S_D
B2: Memory supply
C3: 2025 | D3: 2026 | E3: Unit
B4: HBM | C4: 2845.656 | D4: 3886.3238 | E4: mn GB
B5: DRAM (ex-HBM) | C5: 33505.937 | D5: 39535.398 | E5: mn GB
B6: NAND | C6: 930.69875 | D6: 1114.3898 | E6: EB
B8: # of global models: | C8: 3
E9: AI Inference demand as % of 2026 supply
B10: HBM | D10: =$C$8*'Tier Breakdown'!G58 -> 7474.2043 | E10: =D10/D4 -> 1.9232068
B11: DRAM (ex-HBM) | D11: =$C$8*'Tier Breakdown'!G59 -> 1447474.5 | E11: =D11/D5 -> 36.612112
B12: NAND | D12: =$C$8*('Tier Breakdown'!G61+'Tier Breakdown'!G62)/1000 -> 4640.8132 | E12: =D12/D6 -> 4.1644434
H15: Global demand | L15: as % of global supply
B16: Input tokens / request | C16: HBM TOTAL (PB) | D16: DRAM TOTAL (PB) | E16: Rack SSD TOTAL (EB) | F16: Datalake TOTAL (EB) | H16: HBM | I16: DRAM | J16: NAND | L16: Input tokens / request | M16: DRAM | N16: NAND
B17: 2000 | C17: 226.29073 | D17: 4585.2612 | E17: 46.877348 | F17: 293.556 | H17: =C17*$C$8 -> 678.87219 | I17: =D17*$C$8 -> 13755.784 | J17: =$C$8*(E17+F17) -> 1021.3 | L17: 2000 | M17: =I17/$D$5 -> 0.34793588 | N17: =J17/$D$6 -> 0.91646574
B18: 5000 | C18: 226.29073 | D18: 6648.4656 | E18: 49.972154 | F18: 293.556 | H18: =C18*$C$8 -> 678.87219 | I18: =D18*$C$8 -> 19945.397 | J18: =$C$8*(E18+F18) -> 1030.5845 | L18: 5000 | M18: =I18/$D$5 -> 0.50449464 | N18: =J18/$D$6 -> 0.92479713
B19: 10000 | C19: 226.29073 | D19: 10087.14 | E19: 55.130165 | F19: 293.556 | H19: =C19*$C$8 -> 678.87219 | I19: =D19*$C$8 -> 30261.419 | J19: =$C$8*(E19+F19) -> 1046.0585 | L19: 10000 | M19: =I19/$D$5 -> 0.76542592 | N19: =J19/$D$6 -> 0.93868278
B20: 20000 | C20: 226.29073 | D20: 16964.487 | E20: 65.446187 | F20: 293.556 | H20: =C20*$C$8 -> 678.87219 | I20: =D20*$C$8 -> 50893.462 | J20: =$C$8*(E20+F20) -> 1077.0066 | L20: 20000 | M20: =I20/$D$5 -> 1.2872885 | N20: =J20/$D$6 -> 0.9664541
B21: 50000 | C21: 226.29073 | D21: 37596.531 | E21: 96.394252 | F21: 293.556 | H21: =C21*$C$8 -> 678.87219 | I21: =D21*$C$8 -> 112789.59 | J21: =$C$8*(E21+F21) -> 1169.8508 | L21: 50000 | M21: =I21/$D$5 -> 2.8528761 | N21: =J21/$D$6 -> 1.049768
B22: 100000 | C22: 226.29073 | D22: 71983.27 | E22: 147.97436 | F22: 293.556 | H22: =C22*$C$8 -> 678.87219 | I22: =D22*$C$8 -> 215949.81 | J22: =$C$8*(E22+F22) -> 1324.5911 | L22: 100000 | M22: =I22/$D$5 -> 5.4621888 | N22: =J22/$D$6 -> 1.1886246
B23: 200000 | C23: 226.29073 | D23: 140756.75 | E23: 251.13458 | F23: 293.556 | H23: =C23*$C$8 -> 678.87219 | I23: =D23*$C$8 -> 422270.25 | J23: =$C$8*(E23+F23) -> 1634.0717 | L23: 200000 | M23: =I23/$D$5 -> 10.680814 | N23: =J23/$D$6 -> 1.4663377

Sheet Global S_D (incl. Agentic)
B2: Memory supply
C3: 2025 | D3: 2026 | E3: Unit
B4: HBM | C4: 2845.656 | D4: 3886.3238 | E4: mn GB
B5: DRAM (ex-HBM) | C5: 33505.937 | D5: 39535.398 | E5: mn GB
B6: NAND | C6: 930.69875 | D6: 1114.3898 | E6: EB
B8: # of global models: | C8: 3
E9: AI Inference demand as % of 2026 supply
B10: HBM | D10: =$C$8*'Tier Breakdown'!G58 -> 7474.2043 | E10: =D10/D4 -> 1.9232068
B11: DRAM (ex-HBM) | D11: =$C$8*'Tier Breakdown'!G59 -> 1447474.5 | E11: =D11/D5 -> 36.612112
B12: NAND | D12: =$C$8*('Tier Breakdown'!G61+'Tier Breakdown'!G62)/1000 -> 4640.8132 | E12: =D12/D6 -> 4.1644434
H15: Global demand | L15: as % of global supply
B16: Input tokens / request | C16: HBM TOTAL (PB) | D16: DRAM TOTAL (PB) | E16: Rack SSD TOTAL (EB) | F16: Datalake TOTAL (EB) | H16: HBM | I16: DRAM | J16: NAND | L16: Input tokens / request | M16: DRAM | N16: NAND
B17: 2000 | C17: 226.29073 | D17: 4585.2612 | E17: 46.877348 | F17: 293.556 | H17: =C17*$C$8 -> 678.87219 | I17: =D17*$C$8 -> 13755.784 | J17: =$C$8*(E17+F17) -> 1021.3 | L17: 2000 | M17: =I17/$D$5 -> 0.34793588 | N17: =J17/$D$6 -> 0.91646574
B18: 5000 | C18: 226.29073 | D18: 6648.4656 | E18: 49.972154 | F18: 293.556 | H18: =C18*$C$8 -> 678.87219 | I18: =D18*$C$8 -> 19945.397 | J18: =$C$8*(E18+F18) -> 1030.5845 | L18: 5000 | M18: =I18/$D$5 -> 0.50449464 | N18: =J18/$D$6 -> 0.92479713
B19: 10000 | C19: 226.29073 | D19: 10087.14 | E19: 55.130165 | F19: 293.556 | H19: =C19*$C$8 -> 678.87219 | I19: =D19*$C$8 -> 30261.419 | J19: =$C$8*(E19+F19) -> 1046.0585 | L19: 10000 | M19: =I19/$D$5 -> 0.76542592 | N19: =J19/$D$6 -> 0.93868278
B20: 20000 | C20: 226.29073 | D20: 16964.487 | E20: 65.446187 | F20: 293.556 | H20: =C20*$C$8 -> 678.87219 | I20: =D20*$C$8 -> 50893.462 | J20: =$C$8*(E20+F20) -> 1077.0066 | L20: 20000 | M20: =I20/$D$5 -> 1.2872885 | N20: =J20/$D$6 -> 0.9664541
B21: 50000 | C21: 226.29073 | D21: 37596.531 | E21: 96.394252 | F21: 293.556 | H21: =C21*$C$8 -> 678.87219 | I21: =D21*$C$8 -> 112789.59 | J21: =$C$8*(E21+F21) -> 1169.8508 | L21: 50000 | M21: =I21/$D$5 -> 2.8528761 | N21: =J21/$D$6 -> 1.049768
B22: 100000 | C22: 226.29073 | D22: 71983.27 | E22: 147.97436 | F22: 293.556 | H22: =C22*$C$8 -> 678.87219 | I22: =D22*$C$8 -> 215949.81 | J22: =$C$8*(E22+F22) -> 1324.5911 | L22: 100000 | M22: =I22/$D$5 -> 5.4621888 | N22: =J22/$D$6 -> 1.1886246
B23: 200000 | C23: 226.29073 | D23: 140756.75 | E23: 251.13458 | F23: 293.556 | H23: =C23*$C$8 -> 678.87219 | I23: =D23*$C$8 -> 422270.25 | J23: =$C$8*(E23+F23) -> 1634.0717 | L23: 200000 | M23: =I23/$D$5 -> 10.680814 | N23: =J23/$D$6 -> 1.4663377
